<robot name="robosimian_caesar">
  <link name="virtual0">
    <inertial>
      <origin xyz="0 0 0" rpy="0 0 0"/>
      <mass value="0"/>
      <inertia ixx="0" ixy="0" ixz="0" iyy="0" iyz="0" izz="0" />
    </inertial>
  </link>

  <link name="virtual1">
    <inertial>
      <origin xyz="0 0 0" rpy="0 0 0"/>
      <mass value="0"/>
      <inertia ixx="0" ixy="0" ixz="0" iyy="0" iyz="0" izz="0" />
    </inertial>
  </link>

  <link name="virtual2">
    <inertial>
      <origin xyz="0 0 0" rpy="0 0 0"/>
      <mass value="0"/>
      <inertia ixx="0" ixy="0" ixz="0" iyy="0" iyz="0" izz="0" />
    </inertial>
  </link>

   <link name="torso">
      <inertial>
        <mass value="40.000000" />
        <origin xyz="-0.000820 -0.002060 -0.021800" rpy="0 0 0" />
        <inertia ixx="0.248970" ixy="0.000000" ixz="0.000000" iyy="0.703230" iyz="0.001820" izz="0.772560" />
      </inertial>
      <visual>
        <origin xyz="0 0 0" rpy="3.1415926 0 0" />
        <geometry>
           <mesh filename="stl_0_3/robosim_chassis.stl" scale="1 1 1" />
        </geometry>
        <material name="blue">
	      <color rgba="0 0 .8 1" />
        </material>
      </visual>
      <collision group="default">
        <origin rpy="3.1415926 0 0" xyz="0 0 0"/>
        <geometry>
           <box size="0.257 0.50 0.238"/>
        </geometry>
      </collision>
      <collision group="default">
        <origin rpy="3.1415926 0 0" xyz="0 0 0"/>
        <geometry>
           <box size="0.93 0.230 0.238"/>
        </geometry>
      </collision>
      <collision group="default">
        <origin rpy="3.1415926 0 -0.38153" xyz="0.25393 0.075769 0"/>
        <geometry>
           <box size="0.36257 0.23 0.238"/>
        </geometry>
      </collision>
      <collision group="default">
        <origin rpy="3.1415926 0 0.38153" xyz="-0.25393 0.075769 0"/>
        <geometry>
           <box size="0.36257 0.23 0.238"/>
        </geometry>
      </collision>
      <collision group="default">
        <origin rpy="3.1415926 0 0.38153" xyz="0.25393 -0.075769 0"/>
        <geometry>
           <box size="0.36257 0.23 0.238"/>
        </geometry>
      </collision>
      <collision group="default">
        <origin rpy="3.1415926 0 -0.38153" xyz="-0.25393 -0.075769 0"/>
        <geometry>
           <box size="0.36257 0.23 0.238"/>
        </geometry>
      </collision>
      <collision group="default">
        <origin rpy="3.1415926 -0.383972 0.000000" xyz="0.417050 0.000000 -0.158640"/>
        <geometry>
          <cylinder length="0.144" radius="0.05"/>
        </geometry>
      </collision>
   </link>

   <link name="limb1_link0">
      <inertial>
        <mass value="0.000000" />
        <origin xyz="0.000000 0.000000 0.000000" rpy="0 0 0" />
        <inertia ixx="0.000000" ixy="0.000000" ixz="0.000000" iyy="0.000000" iyz="0.000000" izz="0.000000" />
      </inertial>
      <visual>
        <origin xyz="0.000000 0 0" rpy="0 0 0" />
        <geometry>
           <mesh filename="stl_0_3/robosim_fts.stl" scale="1 1 1" />
        </geometry>
      </visual>
      <collision group="default">
        <origin rpy="3.1415 -1.57080 0" xyz="-.025 0 0"/>
        <geometry>
          <cylinder length="0.145" radius="0.05"/>
        </geometry>
      </collision>
   </link>

   <link name="limb1_link1">
      <inertial>
        <mass value="0.429000" />
        <origin xyz="-0.050402 0.012816 0.000000" rpy="0 0 0" />
        <inertia ixx="0.000741" ixy="-0.000215" ixz="0.000000" iyy="0.002044" iyz="0.000000" izz="0.001885" />
      </inertial>
      <visual>
        <origin xyz="0.000000 0 0" rpy="0 0 0" />
        <geometry>
           <mesh filename="stl_0_3/robosim_pitch_link.stl" scale="1 1 1" />
        </geometry>
      </visual>
      <collision group="default">
        <origin rpy="3.1415 -1.57080 0" xyz="-0.07 0 0"/>
        <geometry>
          <cylinder length="0.07" radius="0.055"/>
        </geometry>
      </collision>
   </link>

   <link name="limb1_link2">
      <inertial>
        <mass value="3.975000" />
        <origin xyz="0.067354 -0.096472 0.000262" rpy="0 0 0" />
        <inertia ixx="0.044712" ixy="-0.030354" ixz="0.000012" iyy="0.033445" iyz="-0.000141" izz="0.074293" />
      </inertial>
      <visual>
        <origin xyz="0.000000 0 0" rpy="0 0 0" />
        <geometry>
           <mesh filename="stl_0_3/robosim_roll_link.stl" scale="1 1 1" />
        </geometry>
      </visual>
      <collision group="default">
        <origin rpy="3.1415 -1.57080 0" xyz="0.065 -0.12 0"/>
        <geometry>
          <cylinder length="0.24" radius="0.055"/>
        </geometry>
      </collision>
      <collision group="default">
        <origin rpy="1.57080 1.57080 0.0" xyz="0.0 -0.035 0"/>
        <geometry>
          <cylinder length="0.075" radius="0.055"/>
        </geometry>
      </collision>
   </link>

   <link name="limb1_link3">
      <inertial>
        <mass value="0.429000" />
        <origin xyz="-0.050402 0.012816 0.000000" rpy="0 0 0" />
        <inertia ixx="0.000741" ixy="-0.000215" ixz="0.000000" iyy="0.002044" iyz="0.000000" izz="0.001885" />
      </inertial>
      <visual>
        <origin xyz="0.000000 0 0" rpy="0 0 0" />
        <geometry>
           <mesh filename="stl_0_3/robosim_pitch_link.stl" scale="1 1 1" />
        </geometry>
      </visual>
      <collision group="default">
        <origin rpy="3.1415 -1.57080 0" xyz="-0.07 0 0"/>
        <geometry>
          <cylinder length="0.07" radius="0.055"/>
        </geometry>
      </collision>
   </link>

   <link name="limb1_link4">
      <inertial>
        <mass value="3.975000" />
        <origin xyz="0.067354 -0.096472 0.000262" rpy="0 0 0" />
        <inertia ixx="0.044712" ixy="-0.030354" ixz="0.000012" iyy="0.033445" iyz="-0.000141" izz="0.074293" />
      </inertial>
      <visual>
        <origin xyz="0.000000 0 0" rpy="0 0 0" />
        <geometry>
           <mesh filename="stl_0_3/robosim_roll_link.stl" scale="1 1 1" />
        </geometry>
      </visual>
      <collision group="default">
        <origin rpy="3.1415 -1.57080 0" xyz="0.065 -0.12 0"/>
        <geometry>
          <cylinder length="0.24" radius="0.055"/>
        </geometry>
      </collision>
      <collision group="default">
        <origin rpy="1.57080 1.57080 0.0" xyz="0.0 -0.035 0"/>
        <geometry>
          <cylinder length="0.075" radius="0.055"/>
        </geometry>
      </collision>
   </link>

   <link name="limb1_link5">
      <inertial>
        <mass value="0.429000" />
        <origin xyz="-0.050402 0.012816 0.000000" rpy="0 0 0" />
        <inertia ixx="0.000741" ixy="-0.000215" ixz="0.000000" iyy="0.002044" iyz="0.000000" izz="0.001885" />
      </inertial>
      <visual>
        <origin xyz="0.000000 0 0" rpy="0 0 0" />
        <geometry>
           <mesh filename="stl_0_3/robosim_pitch_link.stl" scale="1 1 1" />
        </geometry>
      </visual>
      <collision group="default">
        <origin rpy="3.1415 -1.57080 0" xyz="-0.07 0 0"/>
        <geometry>
          <cylinder length="0.07" radius="0.055"/>
        </geometry>
      </collision>
   </link>

   <link name="limb1_link6">
      <inertial>
        <mass value="3.975000" />
        <origin xyz="0.067354 -0.096472 0.000262" rpy="0 0 0" />
        <inertia ixx="0.044712" ixy="-0.030354" ixz="0.000012" iyy="0.033445" iyz="-0.000141" izz="0.074293" />
      </inertial>
      <visual>
        <origin xyz="0.000000 0 0" rpy="0 0 0" />
        <geometry>
           <mesh filename="stl_0_3/robosim_roll_link.stl" scale="1 1 1" />
        </geometry>
      </visual>
      <collision group="default">
        <origin rpy="3.1415 -1.57080 0" xyz="0.065 -0.12 0"/>
        <geometry>
          <cylinder length="0.24" radius="0.055"/>
        </geometry>
      </collision>
      <collision group="default">
        <origin rpy="1.57080 1.57080 0.0" xyz="0.0 -0.035 0"/>
        <geometry>
          <cylinder length="0.075" radius="0.055"/>
        </geometry>
      </collision>
   </link>

   <link name="limb1_link7">
      <inertial>
        <mass value="1.760000" />
        <origin xyz="0.112290 -0.000164 0.000000" rpy="0 0 0" />
        <inertia ixx="0.001913" ixy="-0.000007" ixz="0.000000" iyy="0.006680" iyz="0.000000" izz="0.006125" />
      </inertial>
      <visual>
        <origin xyz="0.000000 0 0" rpy="0 0 0" />
        <geometry>
           <mesh filename="stl_0_3/top_limb.stl" scale="0.001 0.001 0.001" />
        </geometry>
      </visual>
      <collision group="default">
        <origin rpy="3.1415 -1.57080 0" xyz="0.073 0 0"/>
        <geometry>
          <cylinder length="0.146" radius="0.05"/>
        </geometry>
      </collision>
   </link>




    <joint name="torso_x" type="prismatic">
      <origin xyz="0.0 0.0 0.0"  rpy="0.00000 -0.00000 0.00000" />
      <axis xyz="1 0 0" />
      <parent link="virtual0" />
      <child link="virtual1" />
      <limit effort="100000.0" lower="-1000" upper="1000" velocity="0"/>
   </joint>

      <joint name="torso_z" type="prismatic">
      <origin xyz="0.0 0.0 0.0"  rpy="0.00000 -0.00000 0.00000" />
      <axis xyz="0 0 1" />
      <parent link="virtual1" />
      <child link="virtual2" />
      <limit effort="100000.0" lower="-1000" upper="1000" velocity="0"/>
   </joint>


   <joint name="torso_a" type="revolute">
      <origin xyz="0.0 0.0 0.0"  rpy="0.00000 -0.00000 0.00000" />
      <axis xyz="0 1 0" />
      <parent link="virtual2" />
      <child link="torso" />
      <limit effort="1000.0" lower="-3" upper="3" velocity="100"/>
   </joint>

   <joint name="limb1_joint0" type="fixed">
      <origin xyz="0.29326 -0.20940 -0.03650"  rpy="0.00000 1.57080 3.1515926" />
      <parent link="torso" />
      <child link="limb1_link0" />
      <axis xyz="0 0 1" />
      <limit effort="1000.0" lower="-3.4906" upper="3.4906" velocity="0.5"/>
      <dynamics damping="0" friction="0"/>
   </joint>

   <joint name="limb1_joint1" type="fixed">
      <origin xyz="0.17203 0.00000 0.00000"  rpy="3.14159 -0.00000 0.00000" />
      <axis xyz="1 0 0" />
      <parent link="limb1_link0" />
      <child link="limb1_link1" />
      <limit effort="1000.0" lower="-3.1415" upper="3.1415" velocity="0.5"/>
      <dynamics damping="1.000000" friction="10.000000"/>
   </joint>

   <joint name="limb1_joint2" type="revolute">
      <origin xyz="0.00000 0.00000 0.00000"  rpy="0.00000 -1.5708 0.00000" />
      <axis xyz="0 -1 0" />
      <parent link="limb1_link1" />
      <child link="limb1_link2" />
      <limit effort="1000.0" lower="-3.1415" upper="3.1415" velocity="0.5"/>
      <dynamics damping="1.000000" friction="10.000000"/>
   </joint>

   <joint name="limb1_joint3" type="fixed">
      <origin xyz="0.28650 -0.11700 0.00000"  rpy="0.00000 -0.00000 0.00000" />
      <axis xyz="1 0 0" />
      <parent link="limb1_link2" />
      <child link="limb1_link3" />
      <limit effort="1000.0" lower="-3.1415" upper="3.1415" velocity="0.5"/>
      <dynamics damping="1.000000" friction="10.000000"/>
   </joint>

   <joint name="limb1_joint4" type="revolute">
      <origin xyz="0.00000 0.00000 0.00000"  rpy="0.00000 -0.00000 0.00000" />
      <axis xyz="0 -1 0" />
      <parent link="limb1_link3" />
      <child link="limb1_link4" />
      <limit effort="1000.0" lower="-3.1415" upper="3.1415" velocity="0.5"/>
      <dynamics damping="1.000000" friction="10.000000"/>
   </joint>

   <joint name="limb1_joint5" type="fixed">
      <origin xyz="0.28650 -0.11700 0.00000"  rpy="0.00000 -0.00000 0.00000" />
      <axis xyz="1 0 0" />
      <parent link="limb1_link4" />
      <child link="limb1_link5" />
      <limit effort="1000.0" lower="-3.1415" upper="3.1415" velocity="0.5"/>
      <dynamics damping="1.000000" friction="10.000000"/>
   </joint>

   <joint name="limb1_joint6" type="revolute">
      <origin xyz="0.00000 0.00000 0.00000"  rpy="0.00000 -0.00000 0.00000" />
      <axis xyz="0 -1 0" />
      <parent link="limb1_link5" />
      <child link="limb1_link6" />
      <limit effort="1000.0" lower="-3.1415" upper="3.1415" velocity="0.5"/>
      <dynamics damping="1.000000" friction="10.000000"/>
   </joint>

   <joint name="limb1_joint7" type="revolute">
      <origin xyz="0.19250 -0.11700 0.00000"  rpy="0.00000 -0.00000 0.00000" />
      <axis xyz="1 0 0" />
      <parent link="limb1_link6" />
      <child link="limb1_link7" />
      <limit effort="0.0" lower="0" upper="0" velocity="0"/>
      <dynamics damping="1.000000" friction="10.000000"/>
   </joint>



   <link name="limb2_link0">
      <inertial>
        <mass value="0.000000" />
        <origin xyz="0.000000 0.000000 0.000000" rpy="0 0 0" />
        <inertia ixx="0.000000" ixy="0.000000" ixz="0.000000" iyy="0.000000" iyz="0.000000" izz="0.000000" />
      </inertial>
      <visual>
        <origin xyz="0.000000 0 0" rpy="0 0 0" />
        <geometry>
           <mesh filename="stl_0_3/robosim_fts.stl" scale="1 1 1" />
        </geometry>
      </visual>
      <collision group="default">
        <origin rpy="3.1415 -1.57080 0" xyz="-.025 0 0"/>
        <geometry>
          <cylinder length="0.145" radius="0.05"/>
        </geometry>
      </collision>
   </link>

   <link name="limb2_link1">
      <inertial>
        <mass value="0.429000" />
        <origin xyz="-0.050402 0.012816 0.000000" rpy="0 0 0" />
        <inertia ixx="0.000741" ixy="-0.000215" ixz="0.000000" iyy="0.002044" iyz="0.000000" izz="0.001885" />
      </inertial>
      <visual>
        <origin xyz="0.000000 0 0" rpy="0 0 0" />
        <geometry>
           <mesh filename="stl_0_3/robosim_pitch_link.stl" scale="1 1 1" />
        </geometry>
      </visual>
      <collision group="default">
        <origin rpy="3.1415 -1.57080 0" xyz="-0.07 0 0"/>
        <geometry>
          <cylinder length="0.07" radius="0.055"/>
        </geometry>
      </collision>
   </link>

   <link name="limb2_link2">
      <inertial>
        <mass value="3.975000" />
        <origin xyz="0.067354 -0.096472 0.000262" rpy="0 0 0" />
        <inertia ixx="0.044712" ixy="-0.030354" ixz="0.000012" iyy="0.033445" iyz="-0.000141" izz="0.074293" />
      </inertial>
      <visual>
        <origin xyz="0.000000 0 0" rpy="0 0 0" />
        <geometry>
           <mesh filename="stl_0_3/robosim_roll_link.stl" scale="1 1 1" />
        </geometry>
      </visual>
      <collision group="default">
        <origin rpy="3.1415 -1.57080 0" xyz="0.065 -0.12 0"/>
        <geometry>
          <cylinder length="0.24" radius="0.055"/>
        </geometry>
      </collision>
      <collision group="default">
        <origin rpy="1.57080 1.57080 0.0" xyz="0.0 -0.035 0"/>
        <geometry>
          <cylinder length="0.075" radius="0.055"/>
        </geometry>
      </collision>
   </link>

   <link name="limb2_link3">
      <inertial>
        <mass value="0.429000" />
        <origin xyz="-0.050402 0.012816 0.000000" rpy="0 0 0" />
        <inertia ixx="0.000741" ixy="-0.000215" ixz="0.000000" iyy="0.002044" iyz="0.000000" izz="0.001885" />
      </inertial>
      <visual>
        <origin xyz="0.000000 0 0" rpy="0 0 0" />
        <geometry>
           <mesh filename="stl_0_3/robosim_pitch_link.stl" scale="1 1 1" />
        </geometry>
      </visual>
      <collision group="default">
        <origin rpy="3.1415 -1.57080 0" xyz="-0.07 0 0"/>
        <geometry>
          <cylinder length="0.07" radius="0.055"/>
        </geometry>
      </collision>
   </link>

   <link name="limb2_link4">
      <inertial>
        <mass value="3.975000" />
        <origin xyz="0.067354 -0.096472 0.000262" rpy="0 0 0" />
        <inertia ixx="0.044712" ixy="-0.030354" ixz="0.000012" iyy="0.033445" iyz="-0.000141" izz="0.074293" />
      </inertial>
      <visual>
        <origin xyz="0.000000 0 0" rpy="0 0 0" />
        <geometry>
           <mesh filename="stl_0_3/robosim_roll_link.stl" scale="1 1 1" />
        </geometry>
      </visual>
      <collision group="default">
        <origin rpy="3.1415 -1.57080 0" xyz="0.065 -0.12 0"/>
        <geometry>
          <cylinder length="0.24" radius="0.055"/>
        </geometry>
      </collision>
      <collision group="default">
        <origin rpy="1.57080 1.57080 0.0" xyz="0.0 -0.035 0"/>
        <geometry>
          <cylinder length="0.075" radius="0.055"/>
        </geometry>
      </collision>
   </link>

   <link name="limb2_link5">
      <inertial>
        <mass value="0.429000" />
        <origin xyz="-0.050402 0.012816 0.000000" rpy="0 0 0" />
        <inertia ixx="0.000741" ixy="-0.000215" ixz="0.000000" iyy="0.002044" iyz="0.000000" izz="0.001885" />
      </inertial>
      <visual>
        <origin xyz="0.000000 0 0" rpy="0 0 0" />
        <geometry>
           <mesh filename="stl_0_3/robosim_pitch_link.stl" scale="1 1 1" />
        </geometry>
      </visual>
      <collision group="default">
        <origin rpy="3.1415 -1.57080 0" xyz="-0.07 0 0"/>
        <geometry>
          <cylinder length="0.07" radius="0.055"/>
        </geometry>
      </collision>
   </link>

   <link name="limb2_link6">
      <inertial>
        <mass value="3.975000" />
        <origin xyz="0.067354 -0.096472 0.000262" rpy="0 0 0" />
        <inertia ixx="0.044712" ixy="-0.030354" ixz="0.000012" iyy="0.033445" iyz="-0.000141" izz="0.074293" />
      </inertial>
      <visual>
        <origin xyz="0.000000 0 0" rpy="0 0 0" />
        <geometry>
           <mesh filename="stl_0_3/robosim_roll_link.stl" scale="1 1 1" />
        </geometry>
      </visual>
      <collision group="default">
        <origin rpy="3.1415 -1.57080 0" xyz="0.065 -0.12 0"/>
        <geometry>
          <cylinder length="0.24" radius="0.055"/>
        </geometry>
      </collision>
      <collision group="default">
        <origin rpy="1.57080 1.57080 0.0" xyz="0.0 -0.035 0"/>
        <geometry>
          <cylinder length="0.075" radius="0.055"/>
        </geometry>
      </collision>
      <collision group="default">
        <origin rpy="1.57080 1.57080 0.0" xyz="0.0 -0.19 0"/>
        <geometry>
          <cylinder length="0.0375" radius="0.080"/>
        </geometry>
      </collision>
   </link>

   <link name="limb2_link7">
      <inertial>
        <mass value="1.760000" />
        <origin xyz="0.112290 -0.000164 0.000000" rpy="0 0 0" />
        <inertia ixx="0.001913" ixy="-0.000007" ixz="0.000000" iyy="0.006680" iyz="0.000000" izz="0.006125" />
      </inertial>
      <visual>
        <origin xyz="0.000000 0 0" rpy="0 0 0" />
        <geometry>
           <mesh filename="stl_0_3/bottom_limb.stl" scale="0.001 0.001 0.001" />
        </geometry>
      </visual>
      <collision group="default">
        <origin rpy="3.1415 -1.57080 0" xyz="0.073 0 0"/>
        <geometry>
          <cylinder length="0.146" radius="0.05"/>
        </geometry>
      </collision>
   </link>


   <joint name="limb2_joint0" type="fixed">
      <origin xyz="-0.29326 -0.20940 -0.03650"  rpy="0.00000 1.57080 3.1515926" />
      <parent link="torso" />
      <child link="limb2_link0" />
      <axis xyz="0 0 1" />
      <limit effort="1000.0" lower="-3.4906" upper="3.4906" velocity="0.5"/>
      <dynamics damping="0" friction="0"/>
   </joint>

   <joint name="limb2_joint1" type="fixed">
      <origin xyz="0.17203 0.00000 0.00000"  rpy="3.14159 -0.00000 0.00000" />
      <axis xyz="1 0 0" />
      <parent link="limb2_link0" />
      <child link="limb2_link1" />
      <limit effort="1000.0" lower="-3.1415" upper="3.1415" velocity="0.5"/>
      <dynamics damping="1.000000" friction="10.000000"/>
   </joint>

   <joint name="limb2_joint2" type="revolute">
      <origin xyz="0.00000 0.00000 0.00000"  rpy="0.00000 1.57080 0.00000" />
      <axis xyz="0 -1 0" />
      <parent link="limb2_link1" />
      <child link="limb2_link2" />
      <limit effort="1000.0" lower="-3.1415" upper="3.1415" velocity="0.5"/>
      <dynamics damping="1.000000" friction="10.000000"/>
   </joint>

   <joint name="limb2_joint3" type="fixed">
      <origin xyz="0.28650 -0.11700 0.00000"  rpy="0.00000 -0.00000 0.00000" />
      <axis xyz="1 0 0" />
      <parent link="limb2_link2" />
      <child link="limb2_link3" />
      <limit effort="1000.0" lower="-3.1415" upper="3.1415" velocity="0.5"/>
      <dynamics damping="1.000000" friction="10.000000"/>
   </joint>

   <joint name="limb2_joint4" type="revolute">
      <origin xyz="0.00000 0.00000 0.00000"  rpy="0.00000 -0.00000 0.00000" />
      <axis xyz="0 -1 0" />
      <parent link="limb2_link3" />
      <child link="limb2_link4" />
      <limit effort="1000.0" lower="-3.1415" upper="3.1415" velocity="0.5"/>
      <dynamics damping="1.000000" friction="10.000000"/>
   </joint>

   <joint name="limb2_joint5" type="fixed">
      <origin xyz="0.28650 -0.11700 0.00000"  rpy="0.00000 -0.00000 0.00000" />
      <axis xyz="1 0 0" />
      <parent link="limb2_link4" />
      <child link="limb2_link5" />
      <limit effort="1000.0" lower="-3.1415" upper="3.1415" velocity="0.5"/>
      <dynamics damping="1.000000" friction="10.000000"/>
   </joint>

   <joint name="limb2_joint6" type="revolute">
      <origin xyz="0.00000 0.00000 0.00000"  rpy="0.00000 -0.00000 0.00000" />
      <axis xyz="0 -1 0" />
      <parent link="limb2_link5" />
      <child link="limb2_link6" />
      <limit effort="1000.0" lower="-3.1415" upper="3.1415" velocity="0.5"/>
      <dynamics damping="1.000000" friction="10.000000"/>
   </joint>

   <joint name="limb2_joint7" type="revolute">
      <origin xyz="0.19250 -0.11700 0.00000"  rpy="0.00000 -0.00000 0.00000" />
      <axis xyz="1 0 0" />
      <parent link="limb2_link6" />
      <child link="limb2_link7" />
      <limit effort="0.0" lower="0" upper="0" velocity="0"/>
      <dynamics damping="1.000000" friction="10.000000"/>
   </joint>




   <link name="limb3_link0">
      <inertial>
        <mass value="0.000000" />
        <origin xyz="0.000000 0.000000 0.000000" rpy="0 0 0" />
        <inertia ixx="0.000000" ixy="0.000000" ixz="0.000000" iyy="0.000000" iyz="0.000000" izz="0.000000" />
      </inertial>
      <visual>
        <origin xyz="0.000000 0 0" rpy="0 0 0" />
        <geometry>
           <mesh filename="stl_0_3/robosim_fts.stl" scale="1 1 1" />
        </geometry>
      </visual>
      <collision group="default">
        <origin rpy="3.1415 -1.57080 0" xyz="-.025 0 0"/>
        <geometry>
          <cylinder length="0.145" radius="0.05"/>
        </geometry>
      </collision>
   </link>

   <link name="limb3_link1">
      <inertial>
        <mass value="0.429000" />
        <origin xyz="-0.050402 0.012816 0.000000" rpy="0 0 0" />
        <inertia ixx="0.000741" ixy="-0.000215" ixz="0.000000" iyy="0.002044" iyz="0.000000" izz="0.001885" />
      </inertial>
      <visual>
        <origin xyz="0.000000 0 0" rpy="0 0 0" />
        <geometry>
           <mesh filename="stl_0_3/robosim_pitch_link.stl" scale="1 1 1" />
        </geometry>
      </visual>
      <collision group="default">
        <origin rpy="3.1415 -1.57080 0" xyz="-0.07 0 0"/>
        <geometry>
          <cylinder length="0.07" radius="0.055"/>
        </geometry>
      </collision>
   </link>

   <link name="limb3_link2">
      <inertial>
        <mass value="3.975000" />
        <origin xyz="0.067354 -0.096472 0.000262" rpy="0 0 0" />
        <inertia ixx="0.044712" ixy="-0.030354" ixz="0.000012" iyy="0.033445" iyz="-0.000141" izz="0.074293" />
      </inertial>
      <visual>
        <origin xyz="0.000000 0 0" rpy="0 0 0" />
        <geometry>
           <mesh filename="stl_0_3/robosim_roll_link.stl" scale="1 1 1" />
        </geometry>
      </visual>
      <collision group="default">
        <origin rpy="3.1415 -1.57080 0" xyz="0.065 -0.12 0"/>
        <geometry>
          <cylinder length="0.24" radius="0.055"/>
        </geometry>
      </collision>
      <collision group="default">
        <origin rpy="1.57080 1.57080 0.0" xyz="0.0 -0.035 0"/>
        <geometry>
          <cylinder length="0.075" radius="0.055"/>
        </geometry>
      </collision>
   </link>

   <link name="limb3_link3">
      <inertial>
        <mass value="0.429000" />
        <origin xyz="-0.050402 0.012816 0.000000" rpy="0 0 0" />
        <inertia ixx="0.000741" ixy="-0.000215" ixz="0.000000" iyy="0.002044" iyz="0.000000" izz="0.001885" />
      </inertial>
      <visual>
        <origin xyz="0.000000 0 0" rpy="0 0 0" />
        <geometry>
           <mesh filename="stl_0_3/robosim_pitch_link.stl" scale="1 1 1" />
        </geometry>
      </visual>
      <collision group="default">
        <origin rpy="3.1415 -1.57080 0" xyz="-0.07 0 0"/>
        <geometry>
          <cylinder length="0.07" radius="0.055"/>
        </geometry>
      </collision>
   </link>

   <link name="limb3_link4">
      <inertial>
        <mass value="3.975000" />
        <origin xyz="0.067354 -0.096472 0.000262" rpy="0 0 0" />
        <inertia ixx="0.044712" ixy="-0.030354" ixz="0.000012" iyy="0.033445" iyz="-0.000141" izz="0.074293" />
      </inertial>
      <visual>
        <origin xyz="0.000000 0 0" rpy="0 0 0" />
        <geometry>
           <mesh filename="stl_0_3/robosim_roll_link.stl" scale="1 1 1" />
        </geometry>
      </visual>
      <collision group="default">
        <origin rpy="3.1415 -1.57080 0" xyz="0.065 -0.12 0"/>
        <geometry>
          <cylinder length="0.24" radius="0.055"/>
        </geometry>
      </collision>
      <collision group="default">
        <origin rpy="1.57080 1.57080 0.0" xyz="0.0 -0.035 0"/>
        <geometry>
          <cylinder length="0.075" radius="0.055"/>
        </geometry>
      </collision>
   </link>

   <link name="limb3_link5">
      <inertial>
        <mass value="0.429000" />
        <origin xyz="-0.050402 0.012816 0.000000" rpy="0 0 0" />
        <inertia ixx="0.000741" ixy="-0.000215" ixz="0.000000" iyy="0.002044" iyz="0.000000" izz="0.001885" />
      </inertial>
      <visual>
        <origin xyz="0.000000 0 0" rpy="0 0 0" />
        <geometry>
           <mesh filename="stl_0_3/robosim_pitch_link.stl" scale="1 1 1" />
        </geometry>
      </visual>
      <collision group="default">
        <origin rpy="3.1415 -1.57080 0" xyz="-0.07 0 0"/>
        <geometry>
          <cylinder length="0.07" radius="0.055"/>
        </geometry>
      </collision>
   </link>

   <link name="limb3_link6">
      <inertial>
        <mass value="3.975000" />
        <origin xyz="0.067354 -0.096472 0.000262" rpy="0 0 0" />
        <inertia ixx="0.044712" ixy="-0.030354" ixz="0.000012" iyy="0.033445" iyz="-0.000141" izz="0.074293" />
      </inertial>
      <visual>
        <origin xyz="0.000000 0 0" rpy="0 0 0" />
        <geometry>
           <mesh filename="stl_0_3/robosim_roll_link.stl" scale="1 1 1" />
        </geometry>
      </visual>
      <collision group="default">
        <origin rpy="3.1415 -1.57080 0" xyz="0.065 -0.12 0"/>
        <geometry>
          <cylinder length="0.24" radius="0.055"/>
        </geometry>
      </collision>
      <collision group="default">
        <origin rpy="1.57080 1.57080 0.0" xyz="0.0 -0.035 0"/>
        <geometry>
          <cylinder length="0.075" radius="0.055"/>
        </geometry>
      </collision>
      <collision group="default">
        <origin rpy="1.57080 1.57080 0.0" xyz="0.0 -0.19 0"/>
        <geometry>
          <cylinder length="0.0375" radius="0.080"/>
        </geometry>
      </collision>
   </link>

   <link name="limb3_link7">
      <inertial>
        <mass value="1.760000" />
        <origin xyz="0.112290 -0.000164 0.000000" rpy="0 0 0" />
        <inertia ixx="0.001913" ixy="-0.000007" ixz="0.000000" iyy="0.006680" iyz="0.000000" izz="0.006125" />
      </inertial>
      <visual>
        <origin xyz="0.000000 0 0" rpy="0 0 0" />
        <geometry>
           <mesh filename="stl_0_3/bottom_limb.stl" scale="0.001 0.001 0.001" />
        </geometry>
      </visual>
      <collision group="default">
        <origin rpy="3.1415 -1.57080 0" xyz="0.073 0 0"/>
        <geometry>
          <cylinder length="0.146" radius="0.05"/>
        </geometry>
      </collision>
   </link>


   <joint name="limb3_joint0" type="fixed">
      <origin xyz="-0.29326 0.20940 -0.03650"  rpy="0.00000 1.57080 0" />
      <parent link="torso" />
      <child link="limb3_link0" />
      <axis xyz="0 0 1" />
      <limit effort="1000.0" lower="-3.4906" upper="3.4906" velocity="0.5"/>
      <dynamics damping="0" friction="0"/>
   </joint>

   <joint name="limb3_joint1" type="fixed">
      <origin xyz="0.17203 0.00000 0.00000"  rpy="3.14159 -0.00000 0.00000" />
      <axis xyz="1 0 0" />
      <parent link="limb3_link0" />
      <child link="limb3_link1" />
      <limit effort="1000.0" lower="-3.1415" upper="3.1415" velocity="0.5"/>
      <dynamics damping="1.000000" friction="10.000000"/>
   </joint>

   <joint name="limb3_joint2" type="revolute">
      <origin xyz="0.00000 0.00000 0.00000"  rpy="0.00000 -1.5708 0.00000" />
      <axis xyz="0 -1 0" />
      <parent link="limb3_link1" />
      <child link="limb3_link2" />
      <limit effort="1000.0" lower="-3.1415" upper="3.1415" velocity="0.5"/>
      <dynamics damping="1.000000" friction="10.000000"/>
   </joint>

   <joint name="limb3_joint3" type="fixed">
      <origin xyz="0.28650 -0.11700 0.00000"  rpy="0.00000 -0.00000 0.00000" />
      <axis xyz="1 0 0" />
      <parent link="limb3_link2" />
      <child link="limb3_link3" />
      <limit effort="1000.0" lower="-3.1415" upper="3.1415" velocity="0.5"/>
      <dynamics damping="1.000000" friction="10.000000"/>
   </joint>

   <joint name="limb3_joint4" type="revolute">
      <origin xyz="0.00000 0.00000 0.00000"  rpy="0.00000 -0.00000 0.00000" />
      <axis xyz="0 -1 0" />
      <parent link="limb3_link3" />
      <child link="limb3_link4" />
      <limit effort="1000.0" lower="-3.1415" upper="3.1415" velocity="0.5"/>
      <dynamics damping="1.000000" friction="10.000000"/>
   </joint>

   <joint name="limb3_joint5" type="fixed">
      <origin xyz="0.28650 -0.11700 0.00000"  rpy="0.00000 -0.00000 0.00000" />
      <axis xyz="1 0 0" />
      <parent link="limb3_link4" />
      <child link="limb3_link5" />
      <limit effort="1000.0" lower="-3.1415" upper="3.1415" velocity="0.5"/>
      <dynamics damping="1.000000" friction="10.000000"/>
   </joint>

   <joint name="limb3_joint6" type="revolute">
      <origin xyz="0.00000 0.00000 0.00000"  rpy="0.00000 -0.00000 0.00000" />
      <axis xyz="0 -1 0" />
      <parent link="limb3_link5" />
      <child link="limb3_link6" />
      <limit effort="1000.0" lower="-3.1415" upper="3.1415" velocity="0.5"/>
      <dynamics damping="1.000000" friction="10.000000"/>
   </joint>

   <joint name="limb3_joint7" type="revolute">
      <origin xyz="0.19250 -0.11700 0.00000"  rpy="0.00000 -0.00000 0.00000" />
      <axis xyz="1 0 0" />
      <parent link="limb3_link6" />
      <child link="limb3_link7" />
      <limit effort="0.0" lower="0" upper="0" velocity="0"/>
      <dynamics damping="1.000000" friction="10.000000"/>
   </joint>



   <link name="limb4_link0">
      <inertial>
        <mass value="0.000000" />
        <origin xyz="0.000000 0.000000 0.000000" rpy="0 0 0" />
        <inertia ixx="0.000000" ixy="0.000000" ixz="0.000000" iyy="0.000000" iyz="0.000000" izz="0.000000" />
      </inertial>
      <visual>
        <origin xyz="0.000000 0 0" rpy="0 0 0" />
        <geometry>
           <mesh filename="stl_0_3/robosim_fts.stl" scale="1 1 1" />
        </geometry>
      </visual>
      <collision group="default">
        <origin rpy="3.1415 -1.57080 0" xyz="-.025 0 0"/>
        <geometry>
          <cylinder length="0.145" radius="0.05"/>
        </geometry>
      </collision>
   </link>

   <link name="limb4_link1">
      <inertial>
        <mass value="0.429000" />
        <origin xyz="-0.050402 0.012816 0.000000" rpy="0 0 0" />
        <inertia ixx="0.000741" ixy="-0.000215" ixz="0.000000" iyy="0.002044" iyz="0.000000" izz="0.001885" />
      </inertial>
      <visual>
        <origin xyz="0.000000 0 0" rpy="0 0 0" />
        <geometry>
           <mesh filename="stl_0_3/robosim_pitch_link.stl" scale="1 1 1" />
        </geometry>
      </visual>
      <collision group="default">
        <origin rpy="3.1415 -1.57080 0" xyz="-0.07 0 0"/>
        <geometry>
          <cylinder length="0.07" radius="0.055"/>
        </geometry>
      </collision>
   </link>

   <link name="limb4_link2">
      <inertial>
        <mass value="3.975000" />
        <origin xyz="0.067354 -0.096472 0.000262" rpy="0 0 0" />
        <inertia ixx="0.044712" ixy="-0.030354" ixz="0.000012" iyy="0.033445" iyz="-0.000141" izz="0.074293" />
      </inertial>
      <visual>
        <origin xyz="0.000000 0 0" rpy="0 0 0" />
        <geometry>
           <mesh filename="stl_0_3/robosim_roll_link.stl" scale="1 1 1" />
        </geometry>
      </visual>
      <collision group="default">
        <origin rpy="3.1415 -1.57080 0" xyz="0.065 -0.12 0"/>
        <geometry>
          <cylinder length="0.24" radius="0.055"/>
        </geometry>
      </collision>
      <collision group="default">
        <origin rpy="1.57080 1.57080 0.0" xyz="0.0 -0.035 0"/>
        <geometry>
          <cylinder length="0.075" radius="0.055"/>
        </geometry>
      </collision>
   </link>

   <link name="limb4_link3">
      <inertial>
        <mass value="0.429000" />
        <origin xyz="-0.050402 0.012816 0.000000" rpy="0 0 0" />
        <inertia ixx="0.000741" ixy="-0.000215" ixz="0.000000" iyy="0.002044" iyz="0.000000" izz="0.001885" />
      </inertial>
      <visual>
        <origin xyz="0.000000 0 0" rpy="0 0 0" />
        <geometry>
           <mesh filename="stl_0_3/robosim_pitch_link.stl" scale="1 1 1" />
        </geometry>
      </visual>
      <collision group="default">
        <origin rpy="3.1415 -1.57080 0" xyz="-0.07 0 0"/>
        <geometry>
          <cylinder length="0.07" radius="0.055"/>
        </geometry>
      </collision>
   </link>

   <link name="limb4_link4">
      <inertial>
        <mass value="3.975000" />
        <origin xyz="0.067354 -0.096472 0.000262" rpy="0 0 0" />
        <inertia ixx="0.044712" ixy="-0.030354" ixz="0.000012" iyy="0.033445" iyz="-0.000141" izz="0.074293" />
      </inertial>
      <visual>
        <origin xyz="0.000000 0 0" rpy="0 0 0" />
        <geometry>
           <mesh filename="stl_0_3/robosim_roll_link.stl" scale="1 1 1" />
        </geometry>
      </visual>
      <collision group="default">
        <origin rpy="3.1415 -1.57080 0" xyz="0.065 -0.12 0"/>
        <geometry>
          <cylinder length="0.24" radius="0.055"/>
        </geometry>
      </collision>
      <collision group="default">
        <origin rpy="1.57080 1.57080 0.0" xyz="0.0 -0.035 0"/>
        <geometry>
          <cylinder length="0.075" radius="0.055"/>
        </geometry>
      </collision>
   </link>

   <link name="limb4_link5">
      <inertial>
        <mass value="0.429000" />
        <origin xyz="-0.050402 0.012816 0.000000" rpy="0 0 0" />
        <inertia ixx="0.000741" ixy="-0.000215" ixz="0.000000" iyy="0.002044" iyz="0.000000" izz="0.001885" />
      </inertial>
      <visual>
        <origin xyz="0.000000 0 0" rpy="0 0 0" />
        <geometry>
           <mesh filename="stl_0_3/robosim_pitch_link.stl" scale="1 1 1" />
        </geometry>
      </visual>
      <collision group="default">
        <origin rpy="3.1415 -1.57080 0" xyz="-0.07 0 0"/>
        <geometry>
          <cylinder length="0.07" radius="0.055"/>
        </geometry>
      </collision>
   </link>

   <link name="limb4_link6">
      <inertial>
        <mass value="3.975000" />
        <origin xyz="0.067354 -0.096472 0.000262" rpy="0 0 0" />
        <inertia ixx="0.044712" ixy="-0.030354" ixz="0.000012" iyy="0.033445" iyz="-0.000141" izz="0.074293" />
      </inertial>
      <visual>
        <origin xyz="0.000000 0 0" rpy="0 0 0" />
        <geometry>
           <mesh filename="stl_0_3/robosim_roll_link.stl" scale="1 1 1" />
        </geometry>
      </visual>
      <collision group="default">
        <origin rpy="3.1415 -1.57080 0" xyz="0.065 -0.12 0"/>
        <geometry>
          <cylinder length="0.24" radius="0.055"/>
        </geometry>
      </collision>
      <collision group="default">
        <origin rpy="1.57080 1.57080 0.0" xyz="0.0 -0.035 0"/>
        <geometry>
          <cylinder length="0.075" radius="0.055"/>
        </geometry>
      </collision>
   </link>


   <link name="limb4_link7">
      <inertial>
        <mass value="1.760000" />
        <origin xyz="0.112290 -0.000164 0.000000" rpy="0 0 0" />
        <inertia ixx="0.001913" ixy="-0.000007" ixz="0.000000" iyy="0.006680" iyz="0.000000" izz="0.006125" />
      </inertial>
      <visual>
        <origin xyz="0.000000 0 0" rpy="0 0 0" />
        <geometry>
           <mesh filename="stl_0_3/top_limb.stl" scale="0.001 0.001 0.001" />
        </geometry>
      </visual>
      <collision group="default">
        <origin rpy="3.1415 -1.57080 0" xyz="0.073 0 0"/>
        <geometry>
          <cylinder length="0.146" radius="0.05"/>
        </geometry>
      </collision>
   </link>


   <joint name="limb4_joint0" type="fixed">
      <origin xyz="0.29326 0.20940 -0.03650"  rpy="0.00000 1.57080 0" />
      <parent link="torso" />
      <child link="limb4_link0" />
      <axis xyz="0 0 1" />
      <limit effort="1000.0" lower="-3.4906" upper="3.4906" velocity="0.5"/>
      <dynamics damping="0" friction="0"/>
   </joint>

   <joint name="limb4_joint1" type="fixed">
      <origin xyz="0.17203 0.00000 0.00000"  rpy="3.14159 -0.00000 0.00000" />
      <axis xyz="1 0 0" />
      <parent link="limb4_link0" />
      <child link="limb4_link1" />
      <limit effort="1000.0" lower="-3.1415" upper="3.1415" velocity="0.5"/>
      <dynamics damping="1.000000" friction="10.000000"/>
   </joint>

   <joint name="limb4_joint2" type="revolute">
      <origin xyz="0.00000 0.00000 0.00000"  rpy="0.00000 1.5708 0.00000" />
      <axis xyz="0 -1 0" />
      <parent link="limb4_link1" />
      <child link="limb4_link2" />
      <limit effort="1000.0" lower="-3.1415" upper="3.1415" velocity="0.5"/>
      <dynamics damping="1.000000" friction="10.000000"/>
   </joint>

   <joint name="limb4_joint3" type="fixed">
      <origin xyz="0.28650 -0.11700 0.00000"  rpy="0.00000 -0.00000 0.00000" />
      <axis xyz="1 0 0" />
      <parent link="limb4_link2" />
      <child link="limb4_link3" />
      <limit effort="1000.0" lower="-3.1415" upper="3.1415" velocity="0.5"/>
      <dynamics damping="1.000000" friction="10.000000"/>
   </joint>

   <joint name="limb4_joint4" type="revolute">
      <origin xyz="0.00000 0.00000 0.00000"  rpy="0.00000 -0.00000 0.00000" />
      <axis xyz="0 -1 0" />
      <parent link="limb4_link3" />
      <child link="limb4_link4" />
      <limit effort="1000.0" lower="-3.1415" upper="3.1415" velocity="0.5"/>
      <dynamics damping="1.000000" friction="10.000000"/>
   </joint>

   <joint name="limb4_joint5" type="fixed">
      <origin xyz="0.28650 -0.11700 0.00000"  rpy="0.00000 -0.00000 0.00000" />
      <axis xyz="1 0 0" />
      <parent link="limb4_link4" />
      <child link="limb4_link5" />
      <limit effort="1000.0" lower="-3.1415" upper="3.1415" velocity="0.5"/>
      <dynamics damping="1.000000" friction="10.000000"/>
   </joint>

   <joint name="limb4_joint6" type="revolute">
      <origin xyz="0.00000 0.00000 0.00000"  rpy="0.00000 -0.00000 0.00000" />
      <axis xyz="0 -1 0" />
      <parent link="limb4_link5" />
      <child link="limb4_link6" />
      <limit effort="1000.0" lower="-3.1415" upper="3.1415" velocity="0.5"/>
      <dynamics damping="1.000000" friction="10.000000"/>
   </joint>


   <joint name="limb4_joint7" type="revolute">
      <origin xyz="0.19250 -0.11700 0.00000"  rpy="0.00000 -0.00000 0.00000" />
      <axis xyz="1 0 0" />
      <parent link="limb4_link6" />
      <child link="limb4_link7" />
      <limit effort="0.0" lower="0" upper="0" velocity="0"/>
      <dynamics damping="1.000000" friction="10.000000"/>
   </joint>

</robot>
